<robot name="onshape"><link name="palm_lower">
        <visual>
            <origin xyz="-0.020095249652862544332 0.025757756134899473244 -0.034722403578460216134" rpy="0 -0 0" />
            <geometry>
                <mesh filename="palm_lower.stl" />
            </geometry>
            <material name="palm_lower_material">
                <color rgba="0.60392156862745094426 0.14901960784313725283 0.14901960784313725283 1.0" />
            </material>
        </visual>
        <collision>
            <origin xyz="-0.020095249652862544332 0.025757756134899473244 -0.034722403578460216134" rpy="0 -0 0" />
            <geometry>
                <mesh filename="palm_lower.stl" />
            </geometry>
        </collision>
        <inertial>
            <origin xyz="0 0 0" rpy="0 0 0" />
            <mass value="0.237" />
            <inertia ixx="0.000354094" ixy="-0.000001193" ixz="-0.000002445" iyy="0.000260915" iyz="-0.000002905" izz="0.000529257" />
        </inertial>
    </link>

    <joint name="1" type="revolute">
        <origin xyz="-0.0070952496528625457958 0.023057756134899472233 -0.01872240357846021927" rpy="1.5707963267948950037 -1.5707963267948945596 0" />
        <parent link="palm_lower" />
        <child link="fingertip" />
        <axis xyz="0 0 -1" />
        <limit effort="0.95" velocity="8.48" lower="-0.314" upper="2.23" />
        <joint_properties friction="0.0" />
    </joint>

    <link name="fingertip">
        <visual>
            <origin xyz="0.013286424108533503169 -0.0061142383865419869249 0.014499999999999497666" rpy="3.141592653589793116 1.1993117970061734707e-33 4.4395481053923607589e-32" />
            <geometry>
                <mesh filename="fingertip.stl" />
            </geometry>
            <material name="fingertip_material">
                <color rgba="0.86666666666666669627 0.86666666666666669627 0.050980392156862744391 1.0" />
            </material>
        </visual>
        <collision>
            <origin xyz="0.013286424108533503169 -0.0061142383865419869249 0.014499999999999497666" rpy="3.141592653589793116 1.1993117970061734707e-33 4.4395481053923607589e-32" />
            <geometry>
                <mesh filename="fingertip.stl" />
            </geometry>
        </collision>
        <inertial>
            <origin xyz="0 0 0" rpy="0 0 0" />
            <mass value="0.016" />
            <inertia ixx="0.000003368" ixy="0.000000115" ixz="0" iyy="0.000001556" iyz="0" izz="0.000002863" />
        </inertial>
    </link>

    <joint name="12" type="revolute">
        <origin xyz="-0.069395249652862533996 -0.0012422438651005258004 -0.021622403578460215601" rpy="-8.2381766464939424156e-17 1.5707963267948956698 0" />
        <parent link="palm_lower" />
        <child link="pip_4" />
        <axis xyz="0 0 -1" />
        <limit effort="0.95" velocity="8.48" lower="-0.349" upper="2.094" />
        <joint_properties friction="0.0" />
    </joint>

    <link name="pip_4">
        <visual>
            <origin xyz="-0.0053566369077286714317 0.00029999999999999991951 0.00078403401041737819099" rpy="-1.570796326794896558 -1.570796326794896336 0" />
            <geometry>
                <mesh filename="pip.stl" />
            </geometry>
            <material name="pip_material">
                <color rgba="0.74901960784313725839 0.74901960784313725839 0.74901960784313725839 1.0" />
            </material>
        </visual>
        <collision>
            <origin xyz="-0.0053566369077286714317 0.00029999999999999991951 0.00078403401041737819099" rpy="-1.570796326794896558 -1.570796326794896336 0" />
            <geometry>
                <mesh filename="pip.stl" />
            </geometry>
        </collision>
        <inertial>
            <origin xyz="0 0 0" rpy="0 0 0" />
            <mass value="0.032" />
            <inertia ixx="0.000004798" ixy="0.000000012" ixz="0.000000004" iyy="0.000002862" iyz="0.000000011" izz="0.000004234" />
        </inertial>
    </link>

    <joint name="13" type="revolute">
        <origin xyz="-2.7755575615628913511e-17 0.014300000000000005415 -0.013000000000000011546" rpy="1.5707963267948958919 -1.570796326794896336 0" />
        <parent link="pip_4" />
        <child link="thumb_pip" />
        <axis xyz="0 0 -1" />
        <limit effort="0.95" velocity="8.48" lower="-0.47" upper="2.443" />
        <joint_properties friction="0.0" />
    </joint>

    <link name="thumb_pip">
        <visual>
            <origin xyz="0.011961920770611186859 -5.3082538364890297089e-16 -0.015852648956664199681" rpy="1.570796326794896558 1.6050198443300152637e-46 -3.9204996250525192755e-59" />
            <geometry>
                <mesh filename="thumb_pip.stl" />
            </geometry>
            <material name="thumb_pip_material">
                <color rgba="0.86666666666666669627 0.86666666666666669627 0.050980392156862744391 1.0" />
            </material>
        </visual>
        <collision>
            <origin xyz="0.011961920770611186859 -5.3082538364890297089e-16 -0.015852648956664199681" rpy="1.570796326794896558 1.6050198443300152637e-46 -3.9204996250525192755e-59" />
            <geometry>
                <mesh filename="thumb_pip.stl" />
            </geometry>
        </collision>
        <inertial>
            <origin xyz="0 0 0" rpy="0 0 0" />
            <mass value="0.003" />
            <inertia ixx="0.000000593" ixy="0" ixz="0" iyy="0.000000549" iyz="0" izz="0.000000224" />
        </inertial>
    </link>

    <joint name="15" type="revolute">
        <origin xyz="0 0.014499999999999966041 -0.017000000000000053263" rpy="-1.570796326794896558 3.14 -1.9721522630516624601e-31" />
        <parent link="thumb_pip" />
        <child link="thumb_fingertip" />
        <axis xyz="0 0 -1" />
        <limit effort="0.95" velocity="8.48" lower="-1.20" upper="1.90" />
        <joint_properties friction="0.0" />
    </joint>

    <link name="thumb_fingertip">
        <visual>
            <origin xyz="0.062559538462667388381 0.078459682911396988469 0.048992911807332215068" rpy="4.3790577010156367543e-47 -3.3306690738754701143e-16 1.2042408677791935383e-46" />
            <geometry>
                <mesh filename="thumb_fingertip.stl" />
            </geometry>
            <material name="thumb_fingertip_material">
                <color rgba="0.60392156862745094426 0.14901960784313725283 0.14901960784313725283 1.0" />
            </material>
        </visual>
        <collision>
            <origin xyz="0.062559538462667388381 0.078459682911396988469 0.048992911807332215068" rpy="4.3790577010156367543e-47 -3.3306690738754701143e-16 1.2042408677791935383e-46" />
            <geometry>
                <mesh filename="thumb_fingertip.stl" />
            </geometry>
        </collision>
        <inertial>
            <origin xyz="0 0 0" rpy="0 0 0" />
            <mass value="0.049" />
            <inertia ixx="0.000020372" ixy="-0.000000489" ixz="-0.00000003" iyy="0.000004336" iyz="-0.000000097" izz="0.000019845" />
        </inertial>
    </link>

    <joint name="5" type="revolute">
        <origin xyz="-0.0070952496528625457958 -0.022392243865100525113 -0.01872240357846021927" rpy="1.5707963267948950037 -1.5707963267948945596 0" />
        <parent link="palm_lower" />
        <child link="fingertip_2" />
        <axis xyz="0 0 -1" />
        <limit effort="0.95" velocity="8.48" lower="-0.314" upper="2.23" />
        <joint_properties friction="0.0" />
    </joint>

    <link name="fingertip_2">
        <visual>
            <origin xyz="0.01328642410853349623 -0.0061142383865420008027 0.014499999999999495931" rpy="3.141592653589793116 -4.3179597882835943107e-33 1.4408183216511868558e-31" />
            <geometry>
                <mesh filename="fingertip.stl" />
            </geometry>
            <material name="fingertip_material">
                <color rgba="0.86666666666666669627 0.86666666666666669627 0.050980392156862744391 1.0" />
            </material>
        </visual>
        <collision>
            <origin xyz="0.01328642410853349623 -0.0061142383865420008027 0.014499999999999495931" rpy="3.141592653589793116 -4.3179597882835943107e-33 1.4408183216511868558e-31" />
            <geometry>
                <mesh filename="fingertip.stl" />
            </geometry>
        </collision>
        <inertial>
            <origin xyz="0 0 0" rpy="0 0 0" />
            <mass value="0.016" />
            <inertia ixx="0.000003368" ixy="0.000000115" ixz="0" iyy="0.000001556" iyz="0" izz="0.000002863" />
        </inertial>
    </link>

    <joint name="9" type="revolute">
        <origin xyz="-0.0070952496528625457958 -0.067842243865100515521 -0.01872240357846021927" rpy="1.5707963267948950037 -1.5707963267948945596 0" />
        <parent link="palm_lower" />
        <child link="fingertip_3" />
        <axis xyz="0 0 -1" />
        <limit effort="0.95" velocity="8.48" lower="-0.314" upper="2.23" />
        <joint_properties friction="0.0" />
    </joint>

    <link name="fingertip_3">
        <visual>
            <origin xyz="0.013286424108533501434 -0.0061142383865419869249 0.0144999999999994994" rpy="3.141592653589793116 8.6170716950575402125e-33 1.5565411607615035382e-32" />
            <geometry>
                <mesh filename="fingertip.stl" />
            </geometry>
            <material name="fingertip_material">
                <color rgba="0.86666666666666669627 0.86666666666666669627 0.050980392156862744391 1.0" />
            </material>
        </visual>
        <collision>
            <origin xyz="0.013286424108533501434 -0.0061142383865419869249 0.0144999999999994994" rpy="3.141592653589793116 8.6170716950575402125e-33 1.5565411607615035382e-32" />
            <geometry>
                <mesh filename="fingertip.stl" />
            </geometry>
        </collision>
        <inertial>
            <origin xyz="0 0 0" rpy="0 0 0" />
            <mass value="0.016" />
            <inertia ixx="0.000003368" ixy="0.000000115" ixz="0" iyy="0.000001556" iyz="0" izz="0.000002863" />
        </inertial>
    </link>

    </robot>